Workbook

Sheet STPP
B1: Tracking Serah Terima Pinjam Pakai (STPP)
U3: Cut-Off Tgl 15/08/2025
L4: DATA BUKTI/Foto - Tracking STPP/Pengeluaran/ | Q4: ="RI/"&RIGHT(YEAR(TODAY()),2)&"/"&CHOOSE(MONTH(TODAY()),"I","II","III","IV","V","VI","VII","VIII","IX","X","XI","XII")&"/"&TEXT(SUMIFS(V6:V100030,Q6:Q100030,"RI/"&RIGHT(YEAR(TODAY()),2)&"/"&CHOOSE(MONTH(TODAY()),"I","II","III","IV","V","VI","VII","VIII","IX","X","XI","XII")&"/???")+1,"000") -> RI/26/IX/001 | S4: DATA BUKTI/Foto - Tracking STPP/Penerimaan/
B5: No | C5: No Seri | D5: Deskripsi Barang | E5: Kuantitas | F5: Satuan | G5: Peminta | H5: Penempatan | I5: Tgl NPBG | J5: No. NPBG | K5: Item No | L5: Nama File(.#ext) | M5: Bukti Keluar | N5: Keterangan Keluar | O5: Status | P5: Tgl RI | Q5: Tanda Kembali | R5: Item No2 | S5: Nama File(.#ext2) | T5: Bukti Terima | U5: Keterangan Kembali | V5: HC Tanda Kembali | W5: HC Nama File NPBG | X5: HC Nama File RI
B6: 1 | C6: SN-0001 | D6: BETEL BAJA - 1" | E6: 1 | F6: PCS | G6: TOMY | H6: MAINTENANCE KENDARAAN | I6: 45884 | J6: NA/25/VIII/138 | K6: 87 | L6: NA.25.VIII.138-87 | M6: =IF(L6="","",HYPERLINK(_xlfn.CONCAT($L$4,L6,".jpg"),"Open File")) -> Open File | N6: UNTUK STPP AWAL MAINTENANCE | O6: =IF(AND(Q6<>"",T6<>""),"PASSIVE",IF(AND(J6<>"",M6<>""),"ACTIVE","")) -> ACTIVE | T6: =IF(S6="","",HYPERLINK(_xlfn.CONCAT($S$4,S6,".jpg"),"Open File")) | V6: =IF(AND(Q6<>"",RIGHT(Q6,3)<>""),IF(COUNTIF($Q$6:Q6,Q6)=1,1,0),0) -> 0 | W6: =IF(AND(J6<>"",K6<>""),_xlfn.CONCAT(SUBSTITUTE(J6,"/","."),"-",K6),"") -> NA.25.VIII.138-87 | X6: =IF(AND(Q6<>"",R6<>""),_xlfn.CONCAT(SUBSTITUTE(Q6,"/","."),"-",R6),"")
B7: 2 | C7: SN-0002 | D7: GERINDA POTONG DUDUK - MAKITA / 2414NB / 14" | E7: 1 | F7: PCS | G7: TOMY | H7: MAINTENANCE MA | I7: 45884 | J7: NA/25/VIII/138 | K7: 85 | L7: NA.25.VIII.138-85 | M7: =IF(L7="","",HYPERLINK(_xlfn.CONCAT($L$4,L7,".jpg"),"Open File")) -> Open File | N7: UNTUK STPP AWAL MAINTENANCE | O7: =IF(AND(Q7<>"",T7<>""),"PASSIVE",IF(AND(J7<>"",M7<>""),"ACTIVE","")) -> ACTIVE | T7: =IF(S7="","",HYPERLINK(_xlfn.CONCAT($S$4,S7,".jpg"),"Open File")) | V7: =IF(AND(Q7<>"",RIGHT(Q7,3)<>""),IF(COUNTIF($Q$6:Q7,Q7)=1,1,0),0) -> 0 | W7: =IF(AND(J7<>"",K7<>""),_xlfn.CONCAT(SUBSTITUTE(J7,"/","."),"-",K7),"") -> NA.25.VIII.138-85 | X7: =IF(AND(Q7<>"",R7<>""),_xlfn.CONCAT(SUBSTITUTE(Q7,"/","."),"-",R7),"")
B8: 3 | C8: SN-0003 | D8: GERINDA POTONG DUDUK - MAKITA / M2401B / 14" | E8: 1 | F8: PCS | G8: TOMY | H8: MAINTENANCE MA | I8: 45884 | J8: NA/25/VIII/138 | K8: 84 | L8: NA.25.VIII.138-84 | M8: =IF(L8="","",HYPERLINK(_xlfn.CONCAT($L$4,L8,".jpg"),"Open File")) -> Open File | N8: UNTUK STPP AWAL MAINTENANCE | O8: =IF(AND(Q8<>"",T8<>""),"PASSIVE",IF(AND(J8<>"",M8<>""),"ACTIVE","")) -> ACTIVE | T8: =IF(S8="","",HYPERLINK(_xlfn.CONCAT($S$4,S8,".jpg"),"Open File")) | V8: =IF(AND(Q8<>"",RIGHT(Q8,3)<>""),IF(COUNTIF($Q$6:Q8,Q8)=1,1,0),0) -> 0 | W8: =IF(AND(J8<>"",K8<>""),_xlfn.CONCAT(SUBSTITUTE(J8,"/","."),"-",K8),"") -> NA.25.VIII.138-84 | X8: =IF(AND(Q8<>"",R8<>""),_xlfn.CONCAT(SUBSTITUTE(Q8,"/","."),"-",R8),"")
B9: 4 | C9: SN-0004 | D9: BOR TANGAN - MAKITA / HP1630 / 5/8" (16mm) | E9: 1 | F9: PCS | G9: TOMY | H9: MAINTENANCE MA | I9: 45884 | J9: NA/25/VIII/138 | K9: 83 | L9: NA.25.VIII.138-83 | M9: =IF(L9="","",HYPERLINK(_xlfn.CONCAT($L$4,L9,".jpg"),"Open File")) -> Open File | N9: UNTUK STPP AWAL MAINTENANCE | O9: =IF(AND(Q9<>"",T9<>""),"PASSIVE",IF(AND(J9<>"",M9<>""),"ACTIVE","")) -> ACTIVE | P9: 46106 | Q9: RI/NV/26/III/052 | R9: 1 | T9: =IF(S9="","",HYPERLINK(_xlfn.CONCAT($S$4,S9,".jpg"),"Open File")) | U9: KEMBALI DARI MAINTENANCE KARENA RUSAK DAN MINTA DIPERBAIKI | V9: =IF(AND(Q9<>"",RIGHT(Q9,3)<>""),IF(COUNTIF($Q$6:Q9,Q9)=1,1,0),0) -> 1 | W9: =IF(AND(J9<>"",K9<>""),_xlfn.CONCAT(SUBSTITUTE(J9,"/","."),"-",K9),"") -> NA.25.VIII.138-83 | X9: =IF(AND(Q9<>"",R9<>""),_xlfn.CONCAT(SUBSTITUTE(Q9,"/","."),"-",R9),"") -> RI.NV.26.III.052-1
B10: 5 | C10: SN-0005 | D10: BOR TANGAN - MAKITA / HP1630 / 5/8" (16mm) | E10: 1 | F10: PCS | G10: TOMY | H10: MAINTENANCE MA | I10: 45884 | J10: NA/25/VIII/138 | K10: 82 | L10: NA.25.VIII.138-82 | M10: =IF(L10="","",HYPERLINK(_xlfn.CONCAT($L$4,L10,".jpg"),"Open File")) -> Open File | N10: UNTUK STPP AWAL MAINTENANCE | O10: =IF(AND(Q10<>"",T10<>""),"PASSIVE",IF(AND(J10<>"",M10<>""),"ACTIVE","")) -> ACTIVE | T10: =IF(S10="","",HYPERLINK(_xlfn.CONCAT($S$4,S10,".jpg"),"Open File")) | V10: =IF(AND(Q10<>"",RIGHT(Q10,3)<>""),IF(COUNTIF($Q$6:Q10,Q10)=1,1,0),0) -> 0 | W10: =IF(AND(J10<>"",K10<>""),_xlfn.CONCAT(SUBSTITUTE(J10,"/","."),"-",K10),"") -> NA.25.VIII.138-82 | X10: =IF(AND(Q10<>"",R10<>""),_xlfn.CONCAT(SUBSTITUTE(Q10,"/","."),"-",R10),"")
B11: 6 | C11: SN-0006 | D11: HAND BOR - MODERN / M2150 / 13mm | E11: 1 | F11: PCS | G11: TOMY | H11: MAINTENANCE MA | I11: 45884 | J11: NA/25/VIII/138 | K11: 81 | L11: NA.25.VIII.138-81 | M11: =IF(L11="","",HYPERLINK(_xlfn.CONCAT($L$4,L11,".jpg"),"Open File")) -> Open File | N11: UNTUK STPP AWAL MAINTENANCE | O11: =IF(AND(Q11<>"",T11<>""),"PASSIVE",IF(AND(J11<>"",M11<>""),"ACTIVE","")) -> ACTIVE | T11: =IF(S11="","",HYPERLINK(_xlfn.CONCAT($S$4,S11,".jpg"),"Open File")) | V11: =IF(AND(Q11<>"",RIGHT(Q11,3)<>""),IF(COUNTIF($Q$6:Q11,Q11)=1,1,0),0) -> 0 | W11: =IF(AND(J11<>"",K11<>""),_xlfn.CONCAT(SUBSTITUTE(J11,"/","."),"-",K11),"") -> NA.25.VIII.138-81 | X11: =IF(AND(Q11<>"",R11<>""),_xlfn.CONCAT(SUBSTITUTE(Q11,"/","."),"-",R11),"")
B12: 7 | C12: SN-0007 | D12: HAND GERINDA - BOSCH / GWS 060 / 4" | E12: 1 | F12: PCS | G12: TOMY | H12: MAINTENANCE MA | I12: 45884 | J12: NA/25/VIII/138 | K12: 80 | L12: NA.25.VIII.138-80 | M12: =IF(L12="","",HYPERLINK(_xlfn.CONCAT($L$4,L12,".jpg"),"Open File")) -> Open File | N12: UNTUK STPP AWAL MAINTENANCE | O12: =IF(AND(Q12<>"",T12<>""),"PASSIVE",IF(AND(J12<>"",M12<>""),"ACTIVE","")) -> ACTIVE | T12: =IF(S12="","",HYPERLINK(_xlfn.CONCAT($S$4,S12,".jpg"),"Open File")) | V12: =IF(AND(Q12<>"",RIGHT(Q12,3)<>""),IF(COUNTIF($Q$6:Q12,Q12)=1,1,0),0) -> 0 | W12: =IF(AND(J12<>"",K12<>""),_xlfn.CONCAT(SUBSTITUTE(J12,"/","."),"-",K12),"") -> NA.25.VIII.138-80 | X12: =IF(AND(Q12<>"",R12<>""),_xlfn.CONCAT(SUBSTITUTE(Q12,"/","."),"-",R12),"")
B13: 8 | C13: SN-0008 | D13: HAND GERINDA - BOSCH / GWS 700 / 4" | E13: 1 | F13: PCS | G13: TOMY | H13: MAINTENANCE MA | I13: 45884 | J13: NA/25/VIII/138 | K13: 79 | L13: NA.25.VIII.138-79 | M13: =IF(L13="","",HYPERLINK(_xlfn.CONCAT($L$4,L13,".jpg"),"Open File")) -> Open File | N13: UNTUK STPP AWAL MAINTENANCE | O13: =IF(AND(Q13<>"",T13<>""),"PASSIVE",IF(AND(J13<>"",M13<>""),"ACTIVE","")) -> ACTIVE | T13: =IF(S13="","",HYPERLINK(_xlfn.CONCAT($S$4,S13,".jpg"),"Open File")) | V13: =IF(AND(Q13<>"",RIGHT(Q13,3)<>""),IF(COUNTIF($Q$6:Q13,Q13)=1,1,0),0) -> 0 | W13: =IF(AND(J13<>"",K13<>""),_xlfn.CONCAT(SUBSTITUTE(J13,"/","."),"-",K13),"") -> NA.25.VIII.138-79 | X13: =IF(AND(Q13<>"",R13<>""),_xlfn.CONCAT(SUBSTITUTE(Q13,"/","."),"-",R13),"")
B14: 9 | C14: SN-0009 | D14: HAND GERINDA - MAKITA (MAKTEC) / MT 90 / 4" | E14: 1 | F14: PCS | G14: TOMY | H14: MAINTENANCE KENDARAAN | I14: 45884 | J14: NA/25/VIII/138 | K14: 78 | L14: NA.25.VIII.138-78 | M14: =IF(L14="","",HYPERLINK(_xlfn.CONCAT($L$4,L14,".jpg"),"Open File")) -> Open File | N14: UNTUK STPP AWAL MAINTENANCE | O14: =IF(AND(Q14<>"",T14<>""),"PASSIVE",IF(AND(J14<>"",M14<>""),"ACTIVE","")) -> PASSIVE | P14: 45658 | Q14: RI/NV/25/XI/004 | R14: 1 | S14: RI.NV.25.XI.004-1 | T14: =IF(S14="","",HYPERLINK(_xlfn.CONCAT($S$4,S14,".jpg"),"Open File")) -> Open File | U14: PERMINTAAN UNTUK DIPERBAIKI | V14: =IF(AND(Q14<>"",RIGHT(Q14,3)<>""),IF(COUNTIF($Q$6:Q14,Q14)=1,1,0),0) -> 1 | W14: =IF(AND(J14<>"",K14<>""),_xlfn.CONCAT(SUBSTITUTE(J14,"/","."),"-",K14),"") -> NA.25.VIII.138-78 | X14: =IF(AND(Q14<>"",R14<>""),_xlfn.CONCAT(SUBSTITUTE(Q14,"/","."),"-",R14),"") -> RI.NV.25.XI.004-1
B15: 10 | C15: SN-0010 | D15: KABEL JUMPER AKI - P = 3m | E15: 1 | F15: SET | G15: TOMY | H15: MAINTENANCE MA | I15: 45884 | J15: NA/25/VIII/138 | K15: 77 | L15: NA.25.VIII.138-77 | M15: =IF(L15="","",HYPERLINK(_xlfn.CONCAT($L$4,L15,".jpg"),"Open File")) -> Open File | N15: UNTUK STPP AWAL MAINTENANCE | O15: =IF(AND(Q15<>"",T15<>""),"PASSIVE",IF(AND(J15<>"",M15<>""),"ACTIVE","")) -> ACTIVE | T15: =IF(S15="","",HYPERLINK(_xlfn.CONCAT($S$4,S15,".jpg"),"Open File")) | V15: =IF(AND(Q15<>"",RIGHT(Q15,3)<>""),IF(COUNTIF($Q$6:Q15,Q15)=1,1,0),0) -> 0 | W15: =IF(AND(J15<>"",K15<>""),_xlfn.CONCAT(SUBSTITUTE(J15,"/","."),"-",K15),"") -> NA.25.VIII.138-77 | X15: =IF(AND(Q15<>"",R15<>""),_xlfn.CONCAT(SUBSTITUTE(Q15,"/","."),"-",R15),"")
B16: 11 | C16: SN-0011 | D16: KABEL MASSA LAS - P = 1m | E16: 1 | F16: SET | G16: TOMY | H16: MAINTENANCE MA | I16: 45884 | J16: NA/25/VIII/138 | K16: 76 | L16: NA.25.VIII.138-76 | M16: =IF(L16="","",HYPERLINK(_xlfn.CONCAT($L$4,L16,".jpg"),"Open File")) -> Open File | N16: UNTUK STPP AWAL MAINTENANCE | O16: =IF(AND(Q16<>"",T16<>""),"PASSIVE",IF(AND(J16<>"",M16<>""),"ACTIVE","")) -> PASSIVE | P16: 45912 | Q16: RI/NV/25/IX/069 | R16: 5 | S16: RI.NV.25.IX.069-5 | T16: =IF(S16="","",HYPERLINK(_xlfn.CONCAT($S$4,S16,".jpg"),"Open File")) -> Open File | U16: KEMBALI TUKAR DENGAN MESIN LAS CIGWELD | V16: =IF(AND(Q16<>"",RIGHT(Q16,3)<>""),IF(COUNTIF($Q$6:Q16,Q16)=1,1,0),0) -> 1 | W16: =IF(AND(J16<>"",K16<>""),_xlfn.CONCAT(SUBSTITUTE(J16,"/","."),"-",K16),"") -> NA.25.VIII.138-76 | X16: =IF(AND(Q16<>"",R16<>""),_xlfn.CONCAT(SUBSTITUTE(Q16,"/","."),"-",R16),"") -> RI.NV.25.IX.069-5
B17: 12 | C17: SN-0012 | D17: KABEL MASSA LAS - P = 2m | E17: 1 | F17: SET | G17: TOMY | H17: MAINTENANCE MA | I17: 45884 | J17: NA/25/VIII/138 | K17: 75 | L17: NA.25.VIII.138-75 | M17: =IF(L17="","",HYPERLINK(_xlfn.CONCAT($L$4,L17,".jpg"),"Open File")) -> Open File | N17: UNTUK STPP AWAL MAINTENANCE | O17: =IF(AND(Q17<>"",T17<>""),"PASSIVE",IF(AND(J17<>"",M17<>""),"ACTIVE","")) -> PASSIVE | P17: 45974 | Q17: RI/NV/25/XI/051 | R17: 1 | S17: RI.NV.25.XI.051-1 | T17: =IF(S17="","",HYPERLINK(_xlfn.CONCAT($S$4,S17,".jpg"),"Open File")) -> Open File | U17: KEMBALI KARENA KABEL SUDAH RUSAK DAN PUTUS | V17: =IF(AND(Q17<>"",RIGHT(Q17,3)<>""),IF(COUNTIF($Q$6:Q17,Q17)=1,1,0),0) -> 1 | W17: =IF(AND(J17<>"",K17<>""),_xlfn.CONCAT(SUBSTITUTE(J17,"/","."),"-",K17),"") -> NA.25.VIII.138-75 | X17: =IF(AND(Q17<>"",R17<>""),_xlfn.CONCAT(SUBSTITUTE(Q17,"/","."),"-",R17),"") -> RI.NV.25.XI.051-1
B18: 13 | C18: SN-0013 | D18: KABEL MASSA LAS - P = 4m | E18: 1 | F18: SET | G18: TOMY | H18: MAINTENANCE MA | I18: 45884 | J18: NA/25/VIII/138 | K18: 74 | L18: NA.25.VIII.138-74 | M18: =IF(L18="","",HYPERLINK(_xlfn.CONCAT($L$4,L18,".jpg"),"Open File")) -> Open File | N18: UNTUK STPP AWAL MAINTENANCE | O18: =IF(AND(Q18<>"",T18<>""),"PASSIVE",IF(AND(J18<>"",M18<>""),"ACTIVE","")) -> ACTIVE | T18: =IF(S18="","",HYPERLINK(_xlfn.CONCAT($S$4,S18,".jpg"),"Open File")) | V18: =IF(AND(Q18<>"",RIGHT(Q18,3)<>""),IF(COUNTIF($Q$6:Q18,Q18)=1,1,0),0) -> 0 | W18: =IF(AND(J18<>"",K18<>""),_xlfn.CONCAT(SUBSTITUTE(J18,"/","."),"-",K18),"") -> NA.25.VIII.138-74 | X18: =IF(AND(Q18<>"",R18<>""),_xlfn.CONCAT(SUBSTITUTE(Q18,"/","."),"-",R18),"")
B19: 14 | C19: SN-0014 | D19: KABEL POWER F-to-F - @4slots / P = 10m | E19: 1 | F19: SET | G19: TOMY | H19: MAINTENANCE KENDARAAN | I19: 45884 | J19: NA/25/VIII/138 | K19: 73 | L19: NA.25.VIII.138-73 | M19: =IF(L19="","",HYPERLINK(_xlfn.CONCAT($L$4,L19,".jpg"),"Open File")) -> Open File | N19: UNTUK STPP AWAL MAINTENANCE | O19: =IF(AND(Q19<>"",T19<>""),"PASSIVE",IF(AND(J19<>"",M19<>""),"ACTIVE","")) -> ACTIVE | T19: =IF(S19="","",HYPERLINK(_xlfn.CONCAT($S$4,S19,".jpg"),"Open File")) | V19: =IF(AND(Q19<>"",RIGHT(Q19,3)<>""),IF(COUNTIF($Q$6:Q19,Q19)=1,1,0),0) -> 0 | W19: =IF(AND(J19<>"",K19<>""),_xlfn.CONCAT(SUBSTITUTE(J19,"/","."),"-",K19),"") -> NA.25.VIII.138-73 | X19: =IF(AND(Q19<>"",R19<>""),_xlfn.CONCAT(SUBSTITUTE(Q19,"/","."),"-",R19),"")
B20: 15 | C20: SN-0015 | D20: KABEL POWER F-to-F - @4slots / P = 18m | E20: 1 | F20: SET | G20: TOMY | H20: MAINTENANCE KENDARAAN | I20: 45884 | J20: NA/25/VIII/138 | K20: 72 | L20: NA.25.VIII.138-72 | M20: =IF(L20="","",HYPERLINK(_xlfn.CONCAT($L$4,L20,".jpg"),"Open File")) -> Open File | N20: UNTUK STPP AWAL MAINTENANCE | O20: =IF(AND(Q20<>"",T20<>""),"PASSIVE",IF(AND(J20<>"",M20<>""),"ACTIVE","")) -> ACTIVE | T20: =IF(S20="","",HYPERLINK(_xlfn.CONCAT($S$4,S20,".jpg"),"Open File")) | V20: =IF(AND(Q20<>"",RIGHT(Q20,3)<>""),IF(COUNTIF($Q$6:Q20,Q20)=1,1,0),0) -> 0 | W20: =IF(AND(J20<>"",K20<>""),_xlfn.CONCAT(SUBSTITUTE(J20,"/","."),"-",K20),"") -> NA.25.VIII.138-72 | X20: =IF(AND(Q20<>"",R20<>""),_xlfn.CONCAT(SUBSTITUTE(Q20,"/","."),"-",R20),"")
B21: 16 | C21: SN-0016 | D21: KABEL POWER F-to-F - @4slots / P = 26m | E21: 1 | F21: SET | G21: TOMY | H21: MAINTENANCE MA | I21: 45884 | J21: NA/25/VIII/138 | K21: 71 | L21: NA.25.VIII.138-71 | M21: =IF(L21="","",HYPERLINK(_xlfn.CONCAT($L$4,L21,".jpg"),"Open File")) -> Open File | N21: UNTUK STPP AWAL MAINTENANCE | O21: =IF(AND(Q21<>"",T21<>""),"PASSIVE",IF(AND(J21<>"",M21<>""),"ACTIVE","")) -> ACTIVE | T21: =IF(S21="","",HYPERLINK(_xlfn.CONCAT($S$4,S21,".jpg"),"Open File")) | V21: =IF(AND(Q21<>"",RIGHT(Q21,3)<>""),IF(COUNTIF($Q$6:Q21,Q21)=1,1,0),0) -> 0 | W21: =IF(AND(J21<>"",K21<>""),_xlfn.CONCAT(SUBSTITUTE(J21,"/","."),"-",K21),"") -> NA.25.VIII.138-71 | X21: =IF(AND(Q21<>"",R21<>""),_xlfn.CONCAT(SUBSTITUTE(Q21,"/","."),"-",R21),"")
B22: 17 | C22: SN-0017 | D22: KABEL POWER F-to-F - @4slots / P = 29m | E22: 1 | F22: SET | G22: TOMY | H22: MAINTENANCE MA | I22: 45884 | J22: NA/25/VIII/138 | K22: 70 | L22: NA.25.VIII.138-70 | M22: =IF(L22="","",HYPERLINK(_xlfn.CONCAT($L$4,L22,".jpg"),"Open File")) -> Open File | N22: UNTUK STPP AWAL MAINTENANCE | O22: =IF(AND(Q22<>"",T22<>""),"PASSIVE",IF(AND(J22<>"",M22<>""),"ACTIVE","")) -> ACTIVE | T22: =IF(S22="","",HYPERLINK(_xlfn.CONCAT($S$4,S22,".jpg"),"Open File")) | V22: =IF(AND(Q22<>"",RIGHT(Q22,3)<>""),IF(COUNTIF($Q$6:Q22,Q22)=1,1,0),0) -> 0 | W22: =IF(AND(J22<>"",K22<>""),_xlfn.CONCAT(SUBSTITUTE(J22,"/","."),"-",K22),"") -> NA.25.VIII.138-70 | X22: =IF(AND(Q22<>"",R22<>""),_xlfn.CONCAT(SUBSTITUTE(Q22,"/","."),"-",R22),"")
B23: 18 | C23: SN-0018 | D23: KABEL STANG LAS - P = 1.5m | E23: 1 | F23: SET | G23: TOMY | H23: MAINTENANCE MA | I23: 45884 | J23: NA/25/VIII/138 | K23: 69 | L23: NA.25.VIII.138-69 | M23: =IF(L23="","",HYPERLINK(_xlfn.CONCAT($L$4,L23,".jpg"),"Open File")) -> Open File | N23: UNTUK STPP AWAL MAINTENANCE | O23: =IF(AND(Q23<>"",T23<>""),"PASSIVE",IF(AND(J23<>"",M23<>""),"ACTIVE","")) -> PASSIVE | P23: 45912 | Q23: RI/NV/25/IX/069 | R23: 4 | S23: RI.NV.25.IX.069-4 | T23: =IF(S23="","",HYPERLINK(_xlfn.CONCAT($S$4,S23,".jpg"),"Open File")) -> Open File | U23: KEMBALI TUKAR DENGAN MESIN LAS CIGWELD | V23: =IF(AND(Q23<>"",RIGHT(Q23,3)<>""),IF(COUNTIF($Q$6:Q23,Q23)=1,1,0),0) -> 0 | W23: =IF(AND(J23<>"",K23<>""),_xlfn.CONCAT(SUBSTITUTE(J23,"/","."),"-",K23),"") -> NA.25.VIII.138-69 | X23: =IF(AND(Q23<>"",R23<>""),_xlfn.CONCAT(SUBSTITUTE(Q23,"/","."),"-",R23),"") -> RI.NV.25.IX.069-4
B24: 19 | C24: SN-0019 | D24: KABEL STANG LAS - P = 2.5m | E24: 1 | F24: SET | G24: TOMY | H24: MAINTENANCE MA | I24: 45884 | J24: NA/25/VIII/138 | K24: 68 | L24: NA.25.VIII.138-68 | M24: =IF(L24="","",HYPERLINK(_xlfn.CONCAT($L$4,L24,".jpg"),"Open File")) -> Open File | N24: UNTUK STPP AWAL MAINTENANCE | O24: =IF(AND(Q24<>"",T24<>""),"PASSIVE",IF(AND(J24<>"",M24<>""),"ACTIVE","")) -> ACTIVE | T24: =IF(S24="","",HYPERLINK(_xlfn.CONCAT($S$4,S24,".jpg"),"Open File")) | V24: =IF(AND(Q24<>"",RIGHT(Q24,3)<>""),IF(COUNTIF($Q$6:Q24,Q24)=1,1,0),0) -> 0 | W24: =IF(AND(J24<>"",K24<>""),_xlfn.CONCAT(SUBSTITUTE(J24,"/","."),"-",K24),"") -> NA.25.VIII.138-68 | X24: =IF(AND(Q24<>"",R24<>""),_xlfn.CONCAT(SUBSTITUTE(Q24,"/","."),"-",R24),"")
B25: 20 | C25: SN-0020 | D25: KABEL STANG LAS - P = 3m | E25: 1 | F25: SET | G25: TOMY | H25: MAINTENANCE MA | I25: 45884 | J25: NA/25/VIII/138 | K25: 67 | L25: NA.25.VIII.138-67 | M25: =IF(L25="","",HYPERLINK(_xlfn.CONCAT($L$4,L25,".jpg"),"Open File")) -> Open File | N25: UNTUK STPP AWAL MAINTENANCE | O25: =IF(AND(Q25<>"",T25<>""),"PASSIVE",IF(AND(J25<>"",M25<>""),"ACTIVE","")) -> ACTIVE | T25: =IF(S25="","",HYPERLINK(_xlfn.CONCAT($S$4,S25,".jpg"),"Open File")) | V25: =IF(AND(Q25<>"",RIGHT(Q25,3)<>""),IF(COUNTIF($Q$6:Q25,Q25)=1,1,0),0) -> 0 | W25: =IF(AND(J25<>"",K25<>""),_xlfn.CONCAT(SUBSTITUTE(J25,"/","."),"-",K25),"") -> NA.25.VIII.138-67 | X25: =IF(AND(Q25<>"",R25<>""),_xlfn.CONCAT(SUBSTITUTE(Q25,"/","."),"-",R25),"")
B26: 21 | C26: SN-0021 | D26: KABEL STANG LAS - P = 4m | E26: 1 | F26: SET | G26: TOMY | H26: MAINTENANCE MA | I26: 45884 | J26: NA/25/VIII/138 | K26: 66 | L26: NA.25.VIII.138-66 | M26: =IF(L26="","",HYPERLINK(_xlfn.CONCAT($L$4,L26,".jpg"),"Open File")) -> Open File | N26: UNTUK STPP AWAL MAINTENANCE | O26: =IF(AND(Q26<>"",T26<>""),"PASSIVE",IF(AND(J26<>"",M26<>""),"ACTIVE","")) -> PASSIVE | P26: 45975 | Q26: RI/NV/25/XI/053 | R26: 1 | S26: RI.NV.25.XI.053-1 | T26: =IF(S26="","",HYPERLINK(_xlfn.CONCAT($S$4,S26,".jpg"),"Open File")) -> Open File | U26: ALIH FUNGSI JADI KABEL MASSA LAS | V26: =IF(AND(Q26<>"",RIGHT(Q26,3)<>""),IF(COUNTIF($Q$6:Q26,Q26)=1,1,0),0) -> 1 | W26: =IF(AND(J26<>"",K26<>""),_xlfn.CONCAT(SUBSTITUTE(J26,"/","."),"-",K26),"") -> NA.25.VIII.138-66 | X26: =IF(AND(Q26<>"",R26<>""),_xlfn.CONCAT(SUBSTITUTE(Q26,"/","."),"-",R26),"") -> RI.NV.25.XI.053-1
B27: 22 | C27: SN-0022 | D27: KABEL STANG LAS - P = 6m | E27: 1 | F27: SET | G27: TOMY | H27: MAINTENANCE MA | I27: 45884 | J27: NA/25/VIII/138 | K27: 65 | L27: NA.25.VIII.138-65 | M27: =IF(L27="","",HYPERLINK(_xlfn.CONCAT($L$4,L27,".jpg"),"Open File")) -> Open File | N27: UNTUK STPP AWAL MAINTENANCE | O27: =IF(AND(Q27<>"",T27<>""),"PASSIVE",IF(AND(J27<>"",M27<>""),"ACTIVE","")) -> PASSIVE | P27: 46051 | Q27: RI/NV/26/I/106 | R27: 1 | S27: RI.NV.26.I.106-1 | T27: =IF(S27="","",HYPERLINK(_xlfn.CONCAT($S$4,S27,".jpg"),"Open File")) -> Open File | U27: DITARIK SEMENTARA DARI MAINTENANCE UNTUK DILAKUKAN PENGGANTIAN kabel LAS YANG SUDAH RUSAK | V27: =IF(AND(Q27<>"",RIGHT(Q27,3)<>""),IF(COUNTIF($Q$6:Q27,Q27)=1,1,0),0) -> 1 | W27: =IF(AND(J27<>"",K27<>""),_xlfn.CONCAT(SUBSTITUTE(J27,"/","."),"-",K27),"") -> NA.25.VIII.138-65 | X27: =IF(AND(Q27<>"",R27<>""),_xlfn.CONCAT(SUBSTITUTE(Q27,"/","."),"-",R27),"") -> RI.NV.26.I.106-1
B28: 23 | C28: SN-0023 | D28: KABEL STANG LAS - P = 7m | E28: 1 | F28: SET | G28: TOMY | H28: MAINTENANCE MA | I28: 45884 | J28: NA/25/VIII/138 | K28: 64 | L28: NA.25.VIII.138-64 | M28: =IF(L28="","",HYPERLINK(_xlfn.CONCAT($L$4,L28,".jpg"),"Open File")) -> Open File | N28: UNTUK STPP AWAL MAINTENANCE | O28: =IF(AND(Q28<>"",T28<>""),"PASSIVE",IF(AND(J28<>"",M28<>""),"ACTIVE","")) -> PASSIVE | P28: 46058 | Q28: RI/NV/26/II/009 | R28: 1 | S28: RI.NV.26.II.009-1 | T28: =IF(S28="","",HYPERLINK(_xlfn.CONCAT($S$4,S28,".jpg"),"Open File")) -> Open File | U28: DITARIK SEMENTARA DARI MAINTENANCE UNTUK DIGANTI STANG LAS NYA KARENA RUSAK | V28: =IF(AND(Q28<>"",RIGHT(Q28,3)<>""),IF(COUNTIF($Q$6:Q28,Q28)=1,1,0),0) -> 1 | W28: =IF(AND(J28<>"",K28<>""),_xlfn.CONCAT(SUBSTITUTE(J28,"/","."),"-",K28),"") -> NA.25.VIII.138-64 | X28: =IF(AND(Q28<>"",R28<>""),_xlfn.CONCAT(SUBSTITUTE(Q28,"/","."),"-",R28),"") -> RI.NV.26.II.009-1
B29: 24 | C29: SN-0024 | D29: KACAMATA SAFETY - K55 | E29: 1 | F29: PCS | G29: TOMY | H29: MAINTENANCE MA | I29: 45884 | J29: NA/25/VIII/138 | K29: 63 | L29: NA.25.VIII.138-63 | M29: =IF(L29="","",HYPERLINK(_xlfn.CONCAT($L$4,L29,".jpg"),"Open File")) -> Open File | N29: UNTUK STPP AWAL MAINTENANCE | O29: =IF(AND(Q29<>"",T29<>""),"PASSIVE",IF(AND(J29<>"",M29<>""),"ACTIVE","")) -> ACTIVE | T29: =IF(S29="","",HYPERLINK(_xlfn.CONCAT($S$4,S29,".jpg"),"Open File")) | V29: =IF(AND(Q29<>"",RIGHT(Q29,3)<>""),IF(COUNTIF($Q$6:Q29,Q29)=1,1,0),0) -> 0 | W29: =IF(AND(J29<>"",K29<>""),_xlfn.CONCAT(SUBSTITUTE(J29,"/","."),"-",K29),"") -> NA.25.VIII.138-63 | X29: =IF(AND(Q29<>"",R29<>""),_xlfn.CONCAT(SUBSTITUTE(Q29,"/","."),"-",R29),"")
B30: 25 | C30: SN-0025 | D30: KACAMATA SAFETY - K55 | E30: 1 | F30: PCS | G30: TOMY | H30: MAINTENANCE MA | I30: 45884 | J30: NA/25/VIII/138 | K30: 62 | L30: NA.25.VIII.138-62 | M30: =IF(L30="","",HYPERLINK(_xlfn.CONCAT($L$4,L30,".jpg"),"Open File")) -> Open File | N30: UNTUK STPP AWAL MAINTENANCE | O30: =IF(AND(Q30<>"",T30<>""),"PASSIVE",IF(AND(J30<>"",M30<>""),"ACTIVE","")) -> ACTIVE | T30: =IF(S30="","",HYPERLINK(_xlfn.CONCAT($S$4,S30,".jpg"),"Open File")) | V30: =IF(AND(Q30<>"",RIGHT(Q30,3)<>""),IF(COUNTIF($Q$6:Q30,Q30)=1,1,0),0) -> 0 | W30: =IF(AND(J30<>"",K30<>""),_xlfn.CONCAT(SUBSTITUTE(J30,"/","."),"-",K30),"") -> NA.25.VIII.138-62 | X30: =IF(AND(Q30<>"",R30<>""),_xlfn.CONCAT(SUBSTITUTE(Q30,"/","."),"-",R30),"")
B31: 26 | C31: SN-0026 | D31: KIKIR BULAT BESI - LOKAL / 12" | E31: 1 | F31: PCS | G31: TOMY | H31: MAINTENANCE KENDARAAN | I31: 45884 | J31: NA/25/VIII/138 | K31: 61 | L31: NA.25.VIII.138-61 | M31: =IF(L31="","",HYPERLINK(_xlfn.CONCAT($L$4,L31,".jpg"),"Open File")) -> Open File | N31: UNTUK STPP AWAL MAINTENANCE | O31: =IF(AND(Q31<>"",T31<>""),"PASSIVE",IF(AND(J31<>"",M31<>""),"ACTIVE","")) -> ACTIVE | T31: =IF(S31="","",HYPERLINK(_xlfn.CONCAT($S$4,S31,".jpg"),"Open File")) | V31: =IF(AND(Q31<>"",RIGHT(Q31,3)<>""),IF(COUNTIF($Q$6:Q31,Q31)=1,1,0),0) -> 0 | W31: =IF(AND(J31<>"",K31<>""),_xlfn.CONCAT(SUBSTITUTE(J31,"/","."),"-",K31),"") -> NA.25.VIII.138-61 | X31: =IF(AND(Q31<>"",R31<>""),_xlfn.CONCAT(SUBSTITUTE(Q31,"/","."),"-",R31),"")
B32: 27 | C32: SN-0027 | D32: KUNCI GERINDA TANGAN - LOKAL | E32: 1 | F32: PCS | G32: TOMY | H32: MAINTENANCE MA | I32: 45884 | J32: NA/25/VIII/138 | K32: 60 | L32: NA.25.VIII.138-60 | M32: =IF(L32="","",HYPERLINK(_xlfn.CONCAT($L$4,L32,".jpg"),"Open File")) -> Open File | N32: UNTUK STPP AWAL MAINTENANCE | O32: =IF(AND(Q32<>"",T32<>""),"PASSIVE",IF(AND(J32<>"",M32<>""),"ACTIVE","")) -> ACTIVE | T32: =IF(S32="","",HYPERLINK(_xlfn.CONCAT($S$4,S32,".jpg"),"Open File")) | V32: =IF(AND(Q32<>"",RIGHT(Q32,3)<>""),IF(COUNTIF($Q$6:Q32,Q32)=1,1,0),0) -> 0 | W32: =IF(AND(J32<>"",K32<>""),_xlfn.CONCAT(SUBSTITUTE(J32,"/","."),"-",K32),"") -> NA.25.VIII.138-60 | X32: =IF(AND(Q32<>"",R32<>""),_xlfn.CONCAT(SUBSTITUTE(Q32,"/","."),"-",R32),"")
B33: 28 | C33: SN-0028 | D33: KUNCI INGGRIS - CROSSMAN / 95-618 / 18" | E33: 1 | F33: PCS | G33: TOMY | H33: MAINTENANCE MA | I33: 45884 | J33: NA/25/VIII/138 | K33: 59 | L33: NA.25.VIII.138-59 | M33: =IF(L33="","",HYPERLINK(_xlfn.CONCAT($L$4,L33,".jpg"),"Open File")) -> Open File | N33: UNTUK STPP AWAL MAINTENANCE | O33: =IF(AND(Q33<>"",T33<>""),"PASSIVE",IF(AND(J33<>"",M33<>""),"ACTIVE","")) -> ACTIVE | T33: =IF(S33="","",HYPERLINK(_xlfn.CONCAT($S$4,S33,".jpg"),"Open File")) | V33: =IF(AND(Q33<>"",RIGHT(Q33,3)<>""),IF(COUNTIF($Q$6:Q33,Q33)=1,1,0),0) -> 0 | W33: =IF(AND(J33<>"",K33<>""),_xlfn.CONCAT(SUBSTITUTE(J33,"/","."),"-",K33),"") -> NA.25.VIII.138-59 | X33: =IF(AND(Q33<>"",R33<>""),_xlfn.CONCAT(SUBSTITUTE(Q33,"/","."),"-",R33),"")
B34: 29 | C34: SN-0029 | D34: KUNCI INGGRIS - TEKIRO / WR-AD1962 / 12" | E34: 1 | F34: PCS | G34: TOMY | H34: MAINTENANCE MA | I34: 45884 | J34: NA/25/VIII/138 | K34: 58 | L34: NA.25.VIII.138-58 | M34: =IF(L34="","",HYPERLINK(_xlfn.CONCAT($L$4,L34,".jpg"),"Open File")) -> Open File | N34: UNTUK STPP AWAL MAINTENANCE | O34: =IF(AND(Q34<>"",T34<>""),"PASSIVE",IF(AND(J34<>"",M34<>""),"ACTIVE","")) -> ACTIVE | T34: =IF(S34="","",HYPERLINK(_xlfn.CONCAT($S$4,S34,".jpg"),"Open File")) | V34: =IF(AND(Q34<>"",RIGHT(Q34,3)<>""),IF(COUNTIF($Q$6:Q34,Q34)=1,1,0),0) -> 0 | W34: =IF(AND(J34<>"",K34<>""),_xlfn.CONCAT(SUBSTITUTE(J34,"/","."),"-",K34),"") -> NA.25.VIII.138-58 | X34: =IF(AND(Q34<>"",R34<>""),_xlfn.CONCAT(SUBSTITUTE(Q34,"/","."),"-",R34),"")
B35: 30 | C35: SN-0030 | D35: KUNCI INGGRIS - TEKIRO / WR-AD1962 / 12" | E35: 1 | F35: PCS | G35: TOMY | H35: MAINTENANCE MA | I35: 45884 | J35: NA/25/VIII/138 | K35: 57 | L35: NA.25.VIII.138-57 | M35: =IF(L35="","",HYPERLINK(_xlfn.CONCAT($L$4,L35,".jpg"),"Open File")) -> Open File | N35: UNTUK STPP AWAL MAINTENANCE | O35: =IF(AND(Q35<>"",T35<>""),"PASSIVE",IF(AND(J35<>"",M35<>""),"ACTIVE","")) -> ACTIVE | T35: =IF(S35="","",HYPERLINK(_xlfn.CONCAT($S$4,S35,".jpg"),"Open File")) | V35: =IF(AND(Q35<>"",RIGHT(Q35,3)<>""),IF(COUNTIF($Q$6:Q35,Q35)=1,1,0),0) -> 0 | W35: =IF(AND(J35<>"",K35<>""),_xlfn.CONCAT(SUBSTITUTE(J35,"/","."),"-",K35),"") -> NA.25.VIII.138-57 | X35: =IF(AND(Q35<>"",R35<>""),_xlfn.CONCAT(SUBSTITUTE(Q35,"/","."),"-",R35),"")
B36: 31 | C36: SN-0031 | D36: KUNCI INGGRIS CrV - TEKIRO / WR-AD1965 / 24" | E36: 1 | F36: PCS | G36: TOMY | H36: MAINTENANCE MA | I36: 45884 | J36: NA/25/VIII/138 | K36: 56 | L36: NA.25.VIII.138-56 | M36: =IF(L36="","",HYPERLINK(_xlfn.CONCAT($L$4,L36,".jpg"),"Open File")) -> Open File | N36: UNTUK STPP AWAL MAINTENANCE | O36: =IF(AND(Q36<>"",T36<>""),"PASSIVE",IF(AND(J36<>"",M36<>""),"ACTIVE","")) -> ACTIVE | T36: =IF(S36="","",HYPERLINK(_xlfn.CONCAT($S$4,S36,".jpg"),"Open File")) | V36: =IF(AND(Q36<>"",RIGHT(Q36,3)<>""),IF(COUNTIF($Q$6:Q36,Q36)=1,1,0),0) -> 0 | W36: =IF(AND(J36<>"",K36<>""),_xlfn.CONCAT(SUBSTITUTE(J36,"/","."),"-",K36),"") -> NA.25.VIII.138-56 | X36: =IF(AND(Q36<>"",R36<>""),_xlfn.CONCAT(SUBSTITUTE(Q36,"/","."),"-",R36),"")
B37: 32 | C37: SN-0032 | D37: KUNCI PAS - LOKAL / 10 x 12mm | E37: 1 | F37: PCS | G37: TOMY | H37: MAINTENANCE MA | I37: 45884 | J37: NA/25/VIII/138 | K37: 55 | L37: NA.25.VIII.138-55 | M37: =IF(L37="","",HYPERLINK(_xlfn.CONCAT($L$4,L37,".jpg"),"Open File")) -> Open File | N37: UNTUK STPP AWAL MAINTENANCE | O37: =IF(AND(Q37<>"",T37<>""),"PASSIVE",IF(AND(J37<>"",M37<>""),"ACTIVE","")) -> ACTIVE | T37: =IF(S37="","",HYPERLINK(_xlfn.CONCAT($S$4,S37,".jpg"),"Open File")) | V37: =IF(AND(Q37<>"",RIGHT(Q37,3)<>""),IF(COUNTIF($Q$6:Q37,Q37)=1,1,0),0) -> 0 | W37: =IF(AND(J37<>"",K37<>""),_xlfn.CONCAT(SUBSTITUTE(J37,"/","."),"-",K37),"") -> NA.25.VIII.138-55 | X37: =IF(AND(Q37<>"",R37<>""),_xlfn.CONCAT(SUBSTITUTE(Q37,"/","."),"-",R37),"")
B38: 33 | C38: SN-0033 | D38: KUNCI PIPA - INGCO / HPW18182 / 18" | E38: 1 | F38: PCS | G38: TOMY | H38: MAINTENANCE MA | I38: 45884 | J38: NA/25/VIII/138 | K38: 54 | L38: NA.25.VIII.138-54 | M38: =IF(L38="","",HYPERLINK(_xlfn.CONCAT($L$4,L38,".jpg"),"Open File")) -> Open File | N38: UNTUK STPP AWAL MAINTENANCE | O38: =IF(AND(Q38<>"",T38<>""),"PASSIVE",IF(AND(J38<>"",M38<>""),"ACTIVE","")) -> ACTIVE | T38: =IF(S38="","",HYPERLINK(_xlfn.CONCAT($S$4,S38,".jpg"),"Open File")) | V38: =IF(AND(Q38<>"",RIGHT(Q38,3)<>""),IF(COUNTIF($Q$6:Q38,Q38)=1,1,0),0) -> 0 | W38: =IF(AND(J38<>"",K38<>""),_xlfn.CONCAT(SUBSTITUTE(J38,"/","."),"-",K38),"") -> NA.25.VIII.138-54 | X38: =IF(AND(Q38<>"",R38<>""),_xlfn.CONCAT(SUBSTITUTE(Q38,"/","."),"-",R38),"")
B39: 34 | C39: SN-0034 | D39: KUNCI PIPA - TEKIRO / WR-PP0293 / 24" | E39: 1 | F39: PCS | G39: TOMY | H39: MAINTENANCE MA | I39: 45884 | J39: NA/25/VIII/138 | K39: 53 | L39: NA.25.VIII.138-53 | M39: =IF(L39="","",HYPERLINK(_xlfn.CONCAT($L$4,L39,".jpg"),"Open File")) -> Open File | N39: UNTUK STPP AWAL MAINTENANCE | O39: =IF(AND(Q39<>"",T39<>""),"PASSIVE",IF(AND(J39<>"",M39<>""),"ACTIVE","")) -> ACTIVE | T39: =IF(S39="","",HYPERLINK(_xlfn.CONCAT($S$4,S39,".jpg"),"Open File")) | V39: =IF(AND(Q39<>"",RIGHT(Q39,3)<>""),IF(COUNTIF($Q$6:Q39,Q39)=1,1,0),0) -> 0 | W39: =IF(AND(J39<>"",K39<>""),_xlfn.CONCAT(SUBSTITUTE(J39,"/","."),"-",K39),"") -> NA.25.VIII.138-53 | X39: =IF(AND(Q39<>"",R39<>""),_xlfn.CONCAT(SUBSTITUTE(Q39,"/","."),"-",R39),"")
B40: 35 | C40: SN-0035 | D40: KUNCI PIPA CrV - LOKAL / 14" | E40: 1 | F40: PCS | G40: TOMY | H40: MAINTENANCE MA | I40: 45884 | J40: NA/25/VIII/138 | K40: 52 | L40: NA.25.VIII.138-52 | M40: =IF(L40="","",HYPERLINK(_xlfn.CONCAT($L$4,L40,".jpg"),"Open File")) -> Open File | N40: UNTUK STPP AWAL MAINTENANCE | O40: =IF(AND(Q40<>"",T40<>""),"PASSIVE",IF(AND(J40<>"",M40<>""),"ACTIVE","")) -> ACTIVE | T40: =IF(S40="","",HYPERLINK(_xlfn.CONCAT($S$4,S40,".jpg"),"Open File")) | V40: =IF(AND(Q40<>"",RIGHT(Q40,3)<>""),IF(COUNTIF($Q$6:Q40,Q40)=1,1,0),0) -> 0 | W40: =IF(AND(J40<>"",K40<>""),_xlfn.CONCAT(SUBSTITUTE(J40,"/","."),"-",K40),"") -> NA.25.VIII.138-52 | X40: =IF(AND(Q40<>"",R40<>""),_xlfn.CONCAT(SUBSTITUTE(Q40,"/","."),"-",R40),"")
... B62: 57 | C62: SN-0057 | D62: MATA KUNCI SOCK BINTANG CrV - WIPRO / E10 | E62: 1 | F62: PCS | G62: TOMY | H62: MAINTENANCE MA | I62: 45884 | J62: NA/25/VIII/138 | K62: 30 | L62: NA.25.VIII.138-30 | M62: =IF(L62="","",HYPERLINK(_xlfn.CONCAT($L$4,L62,".jpg"),"Open File")) -> Open File | N62: UNTUK STPP AWAL MAINTENANCE | O62: =IF(AND(Q62<>"",T62<>""),"PASSIVE",IF(AND(J62<>"",M62<>""),"ACTIVE","")) -> ACTIVE | T62: =IF(S62="","",HYPERLINK(_xlfn.CONCAT($S$4,S62,".jpg"),"Open File")) | V62: =IF(AND(Q62<>"",RIGHT(Q62,3)<>""),IF(COUNTIF($Q$6:Q62,Q62)=1,1,0),0) -> 0 | W62: =IF(AND(J62<>"",K62<>""),_xlfn.CONCAT(SUBSTITUTE(J62,"/","."),"-",K62),"") -> NA.25.VIII.138-30 | X62: =IF(AND(Q62<>"",R62<>""),_xlfn.CONCAT(SUBSTITUTE(Q62,"/","."),"-",R62),"")
...

Sheet Maintenance
B1: Maintenance STPP
B5: No | C5: No Seri | D5: Deskripsi Barang | E5: Kuantitas | F5: Satuan | G5: Peminta | H5: Tgl NPBG | I5: No NPBG | J5: Keterangan
B6: 1 | C6: SN-0396 | D6: {=IF(C6="","",IFERROR(INDEX(STPP!$D$6:$D$4207,MATCH(C6,STPP!$C$6:$C$4207,0)),"Not Found"))} -> CORONG PLASTIK - LOKAL / @30cm | E6: {=IF(C6="","",IFERROR(INDEX(STPP!$E$6:$E$4207,MATCH(C6,STPP!$C$6:$C$4207,0)),"Not Found"))} -> 1 | F6: {=IF(C6="","",IFERROR(INDEX(STPP!$F$6:$F$4207,MATCH(C6,STPP!$C$6:$C$4207,0)),"Not Found"))} -> PCS | G6: KEVIN | H6: 46142 | I6: NA/26/IV/273 | J6: UNTUK REFILL STPP STIKER REFLEKTIF UNTUK KEBUTUHAN KENDARAAN
B7: 2 | C7: SN-0397 | D7: {=IF(C7="","",IFERROR(INDEX(STPP!$D$6:$D$4207,MATCH(C7,STPP!$C$6:$C$4207,0)),"Not Found"))} -> CORONG PLASTIK - LOKAL / @30cm | E7: {=IF(C7="","",IFERROR(INDEX(STPP!$E$6:$E$4207,MATCH(C7,STPP!$C$6:$C$4207,0)),"Not Found"))} -> 1 | F7: {=IF(C7="","",IFERROR(INDEX(STPP!$F$6:$F$4207,MATCH(C7,STPP!$C$6:$C$4207,0)),"Not Found"))} -> PCS | G7: KEVIN | H7: 46142 | I7: NA/26/IV/273 | J7: UNTUK REFILL STPP STIKER REFLEKTIF UNTUK KEBUTUHAN KENDARAAN
B8: 3 | C8: SN-0193 | D8: {=IF(C8="","",IFERROR(INDEX(STPP!$D$6:$D$4207,MATCH(C8,STPP!$C$6:$C$4207,0)),"Not Found"))} -> CAT SEMPROT KALENG ACRYLIC LACQUER - DITON / 840 / @300cc / PUTIH | E8: {=IF(C8="","",IFERROR(INDEX(STPP!$E$6:$E$4207,MATCH(C8,STPP!$C$6:$C$4207,0)),"Not Found"))} -> 1 | F8: {=IF(C8="","",IFERROR(INDEX(STPP!$F$6:$F$4207,MATCH(C8,STPP!$C$6:$C$4207,0)),"Not Found"))} -> PCS | G8: VALEN | H8: 46175 | I8: NA/26/VI/010 | J8: UNTUK REFILL STPP GUDANG SIG-SDA
B9: 4 | C9: SN-0086 | D9: {=IF(C9="","",IFERROR(INDEX(STPP!$D$6:$D$4207,MATCH(C9,STPP!$C$6:$C$4207,0)),"Not Found"))} -> TOPENG LAS - ROHA | E9: {=IF(C9="","",IFERROR(INDEX(STPP!$E$6:$E$4207,MATCH(C9,STPP!$C$6:$C$4207,0)),"Not Found"))} -> 1 | F9: {=IF(C9="","",IFERROR(INDEX(STPP!$F$6:$F$4207,MATCH(C9,STPP!$C$6:$C$4207,0)),"Not Found"))} -> PCS | G9: KOLIM | H9: 46179 | I9: NA/26/VI/040 | J9: UNTUK PENGGANTIAN KACA FILTER TOPENG LAS KARENA SUDAH BURAM NO SERI ITEM: SN-0086, SN-0398, SN-0305
B10: 5 | C10: SN-0086 | D10: {=IF(C10="","",IFERROR(INDEX(STPP!$D$6:$D$4207,MATCH(C10,STPP!$C$6:$C$4207,0)),"Not Found"))} -> TOPENG LAS - ROHA | E10: {=IF(C10="","",IFERROR(INDEX(STPP!$E$6:$E$4207,MATCH(C10,STPP!$C$6:$C$4207,0)),"Not Found"))} -> 1 | F10: {=IF(C10="","",IFERROR(INDEX(STPP!$F$6:$F$4207,MATCH(C10,STPP!$C$6:$C$4207,0)),"Not Found"))} -> PCS | G10: KOLIM | H10: 46179 | I10: NA/26/VI/040 | J10: UNTUK PENGGANTIAN KACA FILTER TOPENG LAS KARENA SUDAH BURAM NO SERI ITEM: SN-0086, SN-0398, SN-0305
B11: 6 | C11: SN-0398 | D11: {=IF(C11="","",IFERROR(INDEX(STPP!$D$6:$D$4207,MATCH(C11,STPP!$C$6:$C$4207,0)),"Not Found"))} -> (REFURBISHED) TOPENG LAS - ROHA | E11: {=IF(C11="","",IFERROR(INDEX(STPP!$E$6:$E$4207,MATCH(C11,STPP!$C$6:$C$4207,0)),"Not Found"))} -> 1 | F11: {=IF(C11="","",IFERROR(INDEX(STPP!$F$6:$F$4207,MATCH(C11,STPP!$C$6:$C$4207,0)),"Not Found"))} -> PCS | G11: KOLIM | H11: 46179 | I11: NA/26/VI/040 | J11: UNTUK PENGGANTIAN KACA FILTER TOPENG LAS KARENA SUDAH BURAM NO SERI ITEM: SN-0086, SN-0398, SN-0305
B12: 7 | C12: SN-0702 | D12: {=IF(C12="","",IFERROR(INDEX(STPP!$D$6:$D$4207,MATCH(C12,STPP!$C$6:$C$4207,0)),"Not Found"))} -> PRINTER - EPSON / L360 | E12: {=IF(C12="","",IFERROR(INDEX(STPP!$E$6:$E$4207,MATCH(C12,STPP!$C$6:$C$4207,0)),"Not Found"))} -> 1 | F12: {=IF(C12="","",IFERROR(INDEX(STPP!$F$6:$F$4207,MATCH(C12,STPP!$C$6:$C$4207,0)),"Not Found"))} -> PCS | G12: ICA | H12: 46206 | I12: NA/26/VII/019 | J12: UNTUK DIPAKAI KEMBALI SETELAH DILAKUKAN SERVICE
B13: 8 | C13: SN-0716 | D13: {=IF(C13="","",IFERROR(INDEX(STPP!$D$6:$D$4207,MATCH(C13,STPP!$C$6:$C$4207,0)),"Not Found"))} -> PRINTER - HP LASERJET / P1102 | E13: {=IF(C13="","",IFERROR(INDEX(STPP!$E$6:$E$4207,MATCH(C13,STPP!$C$6:$C$4207,0)),"Not Found"))} -> 1 | F13: {=IF(C13="","",IFERROR(INDEX(STPP!$F$6:$F$4207,MATCH(C13,STPP!$C$6:$C$4207,0)),"Not Found"))} -> PCS | G13: YEFINA | H13: 46199 | I13: NA/26/VI/182 | J13: PENGEMBALIAN PRINTER KE RUANG ACC PENJUALAN SETELAH DISERVIS
B14: 9 | C14: SN-0709 | D14: {=IF(C14="","",IFERROR(INDEX(STPP!$D$6:$D$4207,MATCH(C14,STPP!$C$6:$C$4207,0)),"Not Found"))} -> PRINTER - CANON / PIXMA G2010 | E14: {=IF(C14="","",IFERROR(INDEX(STPP!$E$6:$E$4207,MATCH(C14,STPP!$C$6:$C$4207,0)),"Not Found"))} -> 1 | F14: {=IF(C14="","",IFERROR(INDEX(STPP!$F$6:$F$4207,MATCH(C14,STPP!$C$6:$C$4207,0)),"Not Found"))} -> PCS | G14: NIA | H14: 46202 | I14: NA/26/VI/190 | J14: PRINTER DIKEMBALIKAN UNTUK PEMAKAIAN HARIAN SETELAH DILAKUKAN SERVICE
B15: 10 | C15: SN-0680 | D15: {=IF(C15="","",IFERROR(INDEX(STPP!$D$6:$D$4207,MATCH(C15,STPP!$C$6:$C$4207,0)),"Not Found"))} -> PRINTER - CANON / PIXMA G2730 | E15: {=IF(C15="","",IFERROR(INDEX(STPP!$E$6:$E$4207,MATCH(C15,STPP!$C$6:$C$4207,0)),"Not Found"))} -> 1 | F15: {=IF(C15="","",IFERROR(INDEX(STPP!$F$6:$F$4207,MATCH(C15,STPP!$C$6:$C$4207,0)),"Not Found"))} -> PCS | G15: AYU | H15: 46207 | I15: NA/26/VII/025 | J15: UNTUK DIGUNAKAN KEMBALI SETELAH DILAKUKAN SERVICE
B16: 11 | C16: SN-0702 | D16: {=IF(C16="","",IFERROR(INDEX(STPP!$D$6:$D$4207,MATCH(C16,STPP!$C$6:$C$4207,0)),"Not Found"))} -> PRINTER - EPSON / L360 | E16: {=IF(C16="","",IFERROR(INDEX(STPP!$E$6:$E$4207,MATCH(C16,STPP!$C$6:$C$4207,0)),"Not Found"))} -> 1 | F16: {=IF(C16="","",IFERROR(INDEX(STPP!$F$6:$F$4207,MATCH(C16,STPP!$C$6:$C$4207,0)),"Not Found"))} -> PCS | G16: YEFINA | H16: 46206 | I16: NA/26/VII/019 | J16: UNTUK DIPAKAI KEMBALI SETELAH DILAKUKAN SERVICE
B17: 12 | C17: SN-0294 | D17: {=IF(C17="","",IFERROR(INDEX(STPP!$D$6:$D$4207,MATCH(C17,STPP!$C$6:$C$4207,0)),"Not Found"))} -> METERAN SAKU - ATS / 10m | E17: {=IF(C17="","",IFERROR(INDEX(STPP!$E$6:$E$4207,MATCH(C17,STPP!$C$6:$C$4207,0)),"Not Found"))} -> 1 | F17: {=IF(C17="","",IFERROR(INDEX(STPP!$F$6:$F$4207,MATCH(C17,STPP!$C$6:$C$4207,0)),"Not Found"))} -> PCS | G17: SASONGKO | H17: 46179 | I17: NA/26/VI/039 | J17: UNTUK DILAKUKAN PENGGANTIAN KARENA YANG LAMA SUDAH RUSAK
... B21: 16 | C21: SN-0162 | D21: {=IF(C21="","",IFERROR(INDEX(STPP!$D$6:$D$4207,MATCH(C21,STPP!$C$6:$C$4207,0)),"Not Found"))} -> MATA BOR HSS BAJA - NACHI / D = 6mm | E21: {=IF(C21="","",IFERROR(INDEX(STPP!$E$6:$E$4207,MATCH(C21,STPP!$C$6:$C$4207,0)),"Not Found"))} -> 1 | F21: {=IF(C21="","",IFERROR(INDEX(STPP!$F$6:$F$4207,MATCH(C21,STPP!$C$6:$C$4207,0)),"Not Found"))} -> PCS | G21: ARUNG | H21: 46237 | I21: NA/26/VIII/011 | J21: UNTUK MAINTAINING BARANG STPP MILIK GUDANG NO SERI BARANG STPP: SN-0162
D22: {=IF(C22="","",IFERROR(INDEX(STPP!$D$6:$D$4207,MATCH(C22,STPP!$C$6:$C$4207,0)),"Not Found"))} | E22: {=IF(C22="","",IFERROR(INDEX(STPP!$E$6:$E$4207,MATCH(C22,STPP!$C$6:$C$4207,0)),"Not Found"))} | F22: {=IF(C22="","",IFERROR(INDEX(STPP!$F$6:$F$4207,MATCH(C22,STPP!$C$6:$C$4207,0)),"Not Found"))} | G22: =IF(表1[[#This Row],[No Seri]]="","",表1[[#This Row],[Deskripsi Barang]]+表1[[#This Row],[Kuantitas]]-表1[[#This Row],[Satuan]]) | I22: =IF(表1[[#This Row],[Tgl NPBG]]>表1[[#This Row],[Peminta]],表1[[#This Row],[Tgl NPBG]]-表1[[#This Row],[Peminta]],"")
D23: {=IF(C23="","",IFERROR(INDEX(STPP!$D$6:$D$4207,MATCH(C23,STPP!$C$6:$C$4207,0)),"Not Found"))} | E23: {=IF(C23="","",IFERROR(INDEX(STPP!$E$6:$E$4207,MATCH(C23,STPP!$C$6:$C$4207,0)),"Not Found"))} | F23: {=IF(C23="","",IFERROR(INDEX(STPP!$F$6:$F$4207,MATCH(C23,STPP!$C$6:$C$4207,0)),"Not Found"))} | G23: =IF(表1[[#This Row],[No Seri]]="","",表1[[#This Row],[Deskripsi Barang]]+表1[[#This Row],[Kuantitas]]-表1[[#This Row],[Satuan]]) | I23: =IF(表1[[#This Row],[Tgl NPBG]]>表1[[#This Row],[Peminta]],表1[[#This Row],[Tgl NPBG]]-表1[[#This Row],[Peminta]],"")
D24: {=IF(C24="","",IFERROR(INDEX(STPP!$D$6:$D$4207,MATCH(C24,STPP!$C$6:$C$4207,0)),"Not Found"))} | E24: {=IF(C24="","",IFERROR(INDEX(STPP!$E$6:$E$4207,MATCH(C24,STPP!$C$6:$C$4207,0)),"Not Found"))} | F24: {=IF(C24="","",IFERROR(INDEX(STPP!$F$6:$F$4207,MATCH(C24,STPP!$C$6:$C$4207,0)),"Not Found"))} | G24: =IF(表1[[#This Row],[No Seri]]="","",表1[[#This Row],[Deskripsi Barang]]+表1[[#This Row],[Kuantitas]]-表1[[#This Row],[Satuan]]) | I24: =IF(表1[[#This Row],[Tgl NPBG]]>表1[[#This Row],[Peminta]],表1[[#This Row],[Tgl NPBG]]-表1[[#This Row],[Peminta]],"")
D25: {=IF(C25="","",IFERROR(INDEX(STPP!$D$6:$D$4207,MATCH(C25,STPP!$C$6:$C$4207,0)),"Not Found"))} | E25: {=IF(C25="","",IFERROR(INDEX(STPP!$E$6:$E$4207,MATCH(C25,STPP!$C$6:$C$4207,0)),"Not Found"))} | F25: {=IF(C25="","",IFERROR(INDEX(STPP!$F$6:$F$4207,MATCH(C25,STPP!$C$6:$C$4207,0)),"Not Found"))} | G25: =IF(表1[[#This Row],[No Seri]]="","",表1[[#This Row],[Deskripsi Barang]]+表1[[#This Row],[Kuantitas]]-表1[[#This Row],[Satuan]]) | I25: =IF(表1[[#This Row],[Tgl NPBG]]>表1[[#This Row],[Peminta]],表1[[#This Row],[Tgl NPBG]]-表1[[#This Row],[Peminta]],"")
D26: {=IF(C26="","",IFERROR(INDEX(STPP!$D$6:$D$4207,MATCH(C26,STPP!$C$6:$C$4207,0)),"Not Found"))} | E26: {=IF(C26="","",IFERROR(INDEX(STPP!$E$6:$E$4207,MATCH(C26,STPP!$C$6:$C$4207,0)),"Not Found"))} | F26: {=IF(C26="","",IFERROR(INDEX(STPP!$F$6:$F$4207,MATCH(C26,STPP!$C$6:$C$4207,0)),"Not Found"))} | G26: =IF(表1[[#This Row],[No Seri]]="","",表1[[#This Row],[Deskripsi Barang]]+表1[[#This Row],[Kuantitas]]-表1[[#This Row],[Satuan]]) | I26: =IF(表1[[#This Row],[Tgl NPBG]]>表1[[#This Row],[Peminta]],表1[[#This Row],[Tgl NPBG]]-表1[[#This Row],[Peminta]],"")
D27: {=IF(C27="","",IFERROR(INDEX(STPP!$D$6:$D$4207,MATCH(C27,STPP!$C$6:$C$4207,0)),"Not Found"))} | E27: {=IF(C27="","",IFERROR(INDEX(STPP!$E$6:$E$4207,MATCH(C27,STPP!$C$6:$C$4207,0)),"Not Found"))} | F27: {=IF(C27="","",IFERROR(INDEX(STPP!$F$6:$F$4207,MATCH(C27,STPP!$C$6:$C$4207,0)),"Not Found"))} | G27: =IF(表1[[#This Row],[No Seri]]="","",表1[[#This Row],[Deskripsi Barang]]+表1[[#This Row],[Kuantitas]]-表1[[#This Row],[Satuan]]) | I27: =IF(表1[[#This Row],[Tgl NPBG]]>表1[[#This Row],[Peminta]],表1[[#This Row],[Tgl NPBG]]-表1[[#This Row],[Peminta]],"")
D28: {=IF(C28="","",IFERROR(INDEX(STPP!$D$6:$D$4207,MATCH(C28,STPP!$C$6:$C$4207,0)),"Not Found"))} | E28: {=IF(C28="","",IFERROR(INDEX(STPP!$E$6:$E$4207,MATCH(C28,STPP!$C$6:$C$4207,0)),"Not Found"))} | F28: {=IF(C28="","",IFERROR(INDEX(STPP!$F$6:$F$4207,MATCH(C28,STPP!$C$6:$C$4207,0)),"Not Found"))} | G28: =IF(表1[[#This Row],[No Seri]]="","",表1[[#This Row],[Deskripsi Barang]]+表1[[#This Row],[Kuantitas]]-表1[[#This Row],[Satuan]]) | I28: =IF(表1[[#This Row],[Tgl NPBG]]>表1[[#This Row],[Peminta]],表1[[#This Row],[Tgl NPBG]]-表1[[#This Row],[Peminta]],"")
D29: {=IF(C29="","",IFERROR(INDEX(STPP!$D$6:$D$4207,MATCH(C29,STPP!$C$6:$C$4207,0)),"Not Found"))} | E29: {=IF(C29="","",IFERROR(INDEX(STPP!$E$6:$E$4207,MATCH(C29,STPP!$C$6:$C$4207,0)),"Not Found"))} | F29: {=IF(C29="","",IFERROR(INDEX(STPP!$F$6:$F$4207,MATCH(C29,STPP!$C$6:$C$4207,0)),"Not Found"))} | G29: =IF(表1[[#This Row],[No Seri]]="","",表1[[#This Row],[Deskripsi Barang]]+表1[[#This Row],[Kuantitas]]-表1[[#This Row],[Satuan]]) | I29: =IF(表1[[#This Row],[Tgl NPBG]]>表1[[#This Row],[Peminta]],表1[[#This Row],[Tgl NPBG]]-表1[[#This Row],[Peminta]],"")
D30: {=IF(C30="","",IFERROR(INDEX(STPP!$D$6:$D$4207,MATCH(C30,STPP!$C$6:$C$4207,0)),"Not Found"))} | E30: {=IF(C30="","",IFERROR(INDEX(STPP!$E$6:$E$4207,MATCH(C30,STPP!$C$6:$C$4207,0)),"Not Found"))} | F30: {=IF(C30="","",IFERROR(INDEX(STPP!$F$6:$F$4207,MATCH(C30,STPP!$C$6:$C$4207,0)),"Not Found"))} | G30: =IF(表1[[#This Row],[No Seri]]="","",表1[[#This Row],[Deskripsi Barang]]+表1[[#This Row],[Kuantitas]]-表1[[#This Row],[Satuan]]) | I30: =IF(表1[[#This Row],[Tgl NPBG]]>表1[[#This Row],[Peminta]],表1[[#This Row],[Tgl NPBG]]-表1[[#This Row],[Peminta]],"")
D31: {=IF(C31="","",IFERROR(INDEX(STPP!$D$6:$D$4207,MATCH(C31,STPP!$C$6:$C$4207,0)),"Not Found"))} | E31: {=IF(C31="","",IFERROR(INDEX(STPP!$E$6:$E$4207,MATCH(C31,STPP!$C$6:$C$4207,0)),"Not Found"))} | F31: {=IF(C31="","",IFERROR(INDEX(STPP!$F$6:$F$4207,MATCH(C31,STPP!$C$6:$C$4207,0)),"Not Found"))} | G31: =IF(表1[[#This Row],[No Seri]]="","",表1[[#This Row],[Deskripsi Barang]]+表1[[#This Row],[Kuantitas]]-表1[[#This Row],[Satuan]]) | I31: =IF(表1[[#This Row],[Tgl NPBG]]>表1[[#This Row],[Peminta]],表1[[#This Row],[Tgl NPBG]]-表1[[#This Row],[Peminta]],"")
D32: {=IF(C32="","",IFERROR(INDEX(STPP!$D$6:$D$4207,MATCH(C32,STPP!$C$6:$C$4207,0)),"Not Found"))} | E32: {=IF(C32="","",IFERROR(INDEX(STPP!$E$6:$E$4207,MATCH(C32,STPP!$C$6:$C$4207,0)),"Not Found"))} | F32: {=IF(C32="","",IFERROR(INDEX(STPP!$F$6:$F$4207,MATCH(C32,STPP!$C$6:$C$4207,0)),"Not Found"))} | G32: =IF(表1[[#This Row],[No Seri]]="","",表1[[#This Row],[Deskripsi Barang]]+表1[[#This Row],[Kuantitas]]-表1[[#This Row],[Satuan]]) | I32: =IF(表1[[#This Row],[Tgl NPBG]]>表1[[#This Row],[Peminta]],表1[[#This Row],[Tgl NPBG]]-表1[[#This Row],[Peminta]],"")
D33: {=IF(C33="","",IFERROR(INDEX(STPP!$D$6:$D$4207,MATCH(C33,STPP!$C$6:$C$4207,0)),"Not Found"))} | E33: {=IF(C33="","",IFERROR(INDEX(STPP!$E$6:$E$4207,MATCH(C33,STPP!$C$6:$C$4207,0)),"Not Found"))} | F33: {=IF(C33="","",IFERROR(INDEX(STPP!$F$6:$F$4207,MATCH(C33,STPP!$C$6:$C$4207,0)),"Not Found"))} | G33: =IF(表1[[#This Row],[No Seri]]="","",表1[[#This Row],[Deskripsi Barang]]+表1[[#This Row],[Kuantitas]]-表1[[#This Row],[Satuan]]) | I33: =IF(表1[[#This Row],[Tgl NPBG]]>表1[[#This Row],[Peminta]],表1[[#This Row],[Tgl NPBG]]-表1[[#This Row],[Peminta]],"")
... D4188: {=IF(C4188="","",IFERROR(INDEX(STPP!$D$6:$D$4207,MATCH(C4188,STPP!$C$6:$C$4207,0)),"Not Found"))} | E4188: {=IF(C4188="","",IFERROR(INDEX(STPP!$E$6:$E$4207,MATCH(C4188,STPP!$C$6:$C$4207,0)),"Not Found"))} | F4188: {=IF(C4188="","",IFERROR(INDEX(STPP!$F$6:$F$4207,MATCH(C4188,STPP!$C$6:$C$4207,0)),"Not Found"))} | G4188: =IF(表1[[#This Row],[No Seri]]="","",表1[[#This Row],[Deskripsi Barang]]+表1[[#This Row],[Kuantitas]]-表1[[#This Row],[Satuan]]) | I4188: =IF(表1[[#This Row],[Tgl NPBG]]>表1[[#This Row],[Peminta]],表1[[#This Row],[Tgl NPBG]]-表1[[#This Row],[Peminta]],"")

Sheet Dropdown List
A1: Peminta | B1: Penempatan | C1: Deskripsi Ban Lama | D1: No Seri Baru | E1: No Seri Lama
A2: TOMY | B2: MAINTENANCE TABUNG
A3: AGUS | B3: MAINTENANCE KENDARAAN
A4: SONY | B4: DISTRIBUSI
A5: BUDI | B5: GUDANG
A6: ROSUL | B6: GENERAL SERVICE
A7: SAFARI | B7: MAINTENANCE MA
A8: SATRIYO | B8: MAINTENANCE CDO
A9: VANDIKA | B9: GUDANG (PROJECT)
A10: WAHYU | B10: BUDI
A11: ARUNG | B11: W 8202 UW
A12: KEVIN | B12: W 8819 PF
A13: HIDA | B13: W 8602 PE
... A58: FAUZAN | B58: FAUZAN
